---
title: "你真的会有效的处理Promise并发么"
date: 2023-04-19T19:56:20+08:00
---

# 前言

![code.png](https://p9-juejin.byteimg.com/tos-cn-i-k3u1fbpfcp/608d91b4313044118c2bd433ecff3972~tplv-k3u1fbpfcp-zoom-in-crop-mark:1512:0:0:0.awebp?)

> 如上图所示的代码，相信大家在平时的开发中肯定用到不少，我们可以进行优化，**使得只用短短一半的时间就可以完成**。 在上面的函数中，我们等待用户信息请求完成后再请求详情信息。但**这两个函数之间并没有任何关联**，所以**我们可以同时触发两个请求，并同时等待完成**。那么，我们有多少种方式来实现呢？你真的可以处理好`Promise`的并发么？接下来，我们进入正题。

# Promise.all

## 如何实现

> [Promise.all](https://developer.mozilla.org/zh-CN/docs/Web/JavaScript/Reference/Global_Objects/Promise/all) 大家应该是比较熟悉的，`Promise.all`方法接收一个`promise`的`iterable`类型，如果所有传入的`promise`都变成**完成状态**，`Promise.all`返回的 Promise 异步的变为**完成**。如果传入的`promise`中有一个失败(`rejected`),`Promise.all`将失败的结果给失败状态的回调函数，而不管其他`promise`是否完成。 我们可以如下实现刚才的代码

```JavaScript
async function init() {
  const [user, info] = await Promise.all([
    getUser(),
    getInfo()
  ])
  console.log('init', user, info)
}
```

现在这种方式，如果我们之前每个请求都需要 1 秒，**一共需要 2 秒**，那么现在两个**同时执行只需要 1 秒**就完成了！但是这样也有一个问题：我们并没有考虑报错问题。你可能会认为，这个很简单，把代码放在一个`try...cahtch`中不就可以了，就像这样：

```JavaScript
async function init() {
  try {
    const [user, info] = await Promise.all([
      getUser(),
      getInfo()
    ])
    console.log('init ==== ', user, info)
  } catch(err) {
    console.log('err', err);
  }
}
```

但是，这样的话会有一个问题，就像这样：

```JavaScript
function getUser() {
  return new Promise((resolve, reject) => {
    setTimeout(() => {
      reject('user reject')
    }, 500);
  })
}

function getInfo() {
  return new Promise((resolve, reject) => {
    setTimeout(() => {
      reject('info reject')
    }, 1000);
  })
}

// 输出 err user reject
```

由于`getUser`优先完成并出现错误，此时触发了`catch`，而当`getInfo`再次完成并出现错误时，将不会触发`catch`。因为`catch`代码已经运行，函数已经完成。 那么，要怎么做呢？接下来，我们就讲讲应该如何处理报错问题。

## 如何处理报错

解决方式是，给`Promise.all`中的每个函数加上`catch`，如下：

```JavaScript
function handle(err) {
  console.log('err', err)
}

function onReject(err) {
  handle(err);
  return new Error(err);
}

async function init() {
  const [user, info] = await Promise.all([
    getUser().catch(onReject),
    getInfo().catch(onReject)
  ])

  console.log('init', user instanceof Error, info instanceof Error) // init true true
}
```

这样，我们在`onReject`函数中处理错误，并返回这个错误。所以现在我们生成的`user`和`info`要么是`Error`要么是我们期望的效果，而`Error`我们可以用`instanceof`检查它。

# Promise.allSettled

> 解决并发我们还可以使用 [Promise.allSettled](https://developer.mozilla.org/zh-CN/docs/Web/JavaScript/Reference/Global_Objects/Promise/allSettled) ，我们会得到一个包含每个`Promise`结果的值或错误信息。

## 如何实现

接下来，我们来使用一下，代码如下：

```JavaScript
async function init() {
  const [userStatus, infoStatus] = await Promise.allSettled([
    getUser(),
    getInfo()
  ])

  console.log('info', userStatus, infoStatus)
}
```

现在，我们可以得到这样的数据：

![code.png](https://p6-juejin.byteimg.com/tos-cn-i-k3u1fbpfcp/9d49a3c7941d4de29a836f38a1de11ce~tplv-k3u1fbpfcp-zoom-in-crop-mark:1512:0:0:0.awebp?)

结果对象有 3 个属性：

- status: `fulfilled` 或 `rejected`
- value: 仅在`status`为`fulfilled`时出现，为`Promise`为`resolve`返回的值
- reason: 仅在`status`为`rejected`时出现，为`Promise`被`reject`时返回的值

因此，我们可以读取到每个`Promise`的状态，并单独处理每个错误而不会遗漏任何的信息。

# 最后两个技巧

## Promise.race

[Promise.race](https://developer.mozilla.org/zh-CN/docs/Web/JavaScript/Reference/Global_Objects/Promise/race)方法可接受一个可迭代的`promise`返回一个`promise`，一旦迭代器中某个`promise`解决或拒绝，返回的`promise`就会`resolve`或`reject`。

我们可以这样实现一个简单的超时功能，代码如下：

```JavaScript
function getUser() {
  return new Promise((resolve) => {
    setTimeout(() => {
      resolve('user resolve')
    }, 5100);
  })
}

async function init() {
  // Race to see which Promise completes first
  const racePromise = Promise.race([
    getUser(),
    new Promise((resolve, reject) =>
      // Time out after 5 seconds
      setTimeout(() => reject(new Error('Timeout')), 5000)
    )
  ])
  try {
    const result = await racePromise
    console.log('result', result)
  } catch (err) {
    console.log('err', err)
    // Timed out!
  }
}
```

**注意，通常情况下，如果有超时，那么你需要尽量的取消未完成的待处理任务**。

另外，最好还是处理所有`promise`的`reject`：

```JavaScript
const racePromise = Promise.race([
    getUser().catch(onReject),
    // xxx
  ])
```

## Promise.any

[Promise.any](https://developer.mozilla.org/zh-CN/docs/Web/JavaScript/Reference/Global_Objects/Promise/any) 等待任何一个`promise`成功则为成功，只有全部的`promise`都被`reject`，才会返回`reject`。通常我们可以使用`Promise.any`来实现，当一个`promise`先完成后，取消其他的`promise`，不过要注意的是，**我们并不总是同时要处理多个数据，只是因为我们可以做到，所以要谨慎的使用它**。

通常，我们不想出现未被处理的`reject`，所以，我们应该这样写：

```JavaScript
const anyPromise = Promise.any([
    getUser().catch(onReject),
    getInfo().catch(onReject)
])
```

# 总结

> 前面我们已经介绍了在使用`promise`处理并发问题时，应该如何的处理`promise`的`reject`。但是也需要注意：**过度的并发会导致网络抖动、磁盘抖动或其他问题**，虽然可以，但并不是一定要这样做，有时使用`async await`也可以使代码更容易理解和维护，所以，在使用之前我们更需要考虑是否需要。
